2024-04-02 23:55:27,701 ERROR: Exception on /update-first-name [POST] [in /Users/apple/ProjectBackups/Flask_Packages/.venv/lib/python3.12/site-packages/flask/app.py:828]
Traceback (most recent call last):
  File "/Users/apple/ProjectBackups/Flask_Packages/.venv/lib/python3.12/site-packages/sqlalchemy/engine/base.py", line 1960, in _exec_single_context
    self.dialect.do_execute(
  File "/Users/apple/ProjectBackups/Flask_Packages/.venv/lib/python3.12/site-packages/sqlalchemy/engine/default.py", line 924, in do_execute
    cursor.execute(statement, parameters)
sqlite3.IntegrityError: UNIQUE constraint failed: user.first_name

The above exception was the direct cause of the following exception:

Traceback (most recent call last):
  File "/Users/apple/ProjectBackups/Flask_Packages/.venv/lib/python3.12/site-packages/flask/app.py", line 1463, in wsgi_app
    response = self.full_dispatch_request()
               ^^^^^^^^^^^^^^^^^^^^^^^^^^^^
  File "/Users/apple/ProjectBackups/Flask_Packages/.venv/lib/python3.12/site-packages/flask/app.py", line 872, in full_dispatch_request
    rv = self.handle_user_exception(e)
         ^^^^^^^^^^^^^^^^^^^^^^^^^^^^^
  File "/Users/apple/ProjectBackups/Flask_Packages/.venv/lib/python3.12/site-packages/flask/app.py", line 870, in full_dispatch_request
    rv = self.dispatch_request()
         ^^^^^^^^^^^^^^^^^^^^^^^
  File "/Users/apple/ProjectBackups/Flask_Packages/.venv/lib/python3.12/site-packages/flask/app.py", line 855, in dispatch_request
    return self.ensure_sync(self.view_functions[rule.endpoint])(**view_args)  # type: ignore[no-any-return]
           ^^^^^^^^^^^^^^^^^^^^^^^^^^^^^^^^^^^^^^^^^^^^^^^^^^^^^^^^^^^^^^^^^
  File "/Users/apple/ProjectBackups/Flask_Packages/.venv/lib/python3.12/site-packages/flask_login/utils.py", line 290, in decorated_view
    return current_app.ensure_sync(func)(*args, **kwargs)
           ^^^^^^^^^^^^^^^^^^^^^^^^^^^^^^^^^^^^^^^^^^^^^^
  File "/Users/apple/ProjectBackups/Flask_Packages/website/auth/auth.py", line 95, in edit_profile
    db.session.commit()
  File "/Users/apple/ProjectBackups/Flask_Packages/.venv/lib/python3.12/site-packages/sqlalchemy/orm/scoping.py", line 597, in commit
    return self._proxied.commit()
           ^^^^^^^^^^^^^^^^^^^^^^
  File "/Users/apple/ProjectBackups/Flask_Packages/.venv/lib/python3.12/site-packages/sqlalchemy/orm/session.py", line 1972, in commit
    trans.commit(_to_root=True)
  File "<string>", line 2, in commit
  File "/Users/apple/ProjectBackups/Flask_Packages/.venv/lib/python3.12/site-packages/sqlalchemy/orm/state_changes.py", line 139, in _go
    ret_value = fn(self, *arg, **kw)
                ^^^^^^^^^^^^^^^^^^^^
  File "/Users/apple/ProjectBackups/Flask_Packages/.venv/lib/python3.12/site-packages/sqlalchemy/orm/session.py", line 1257, in commit
    self._prepare_impl()
  File "<string>", line 2, in _prepare_impl
  File "/Users/apple/ProjectBackups/Flask_Packages/.venv/lib/python3.12/site-packages/sqlalchemy/orm/state_changes.py", line 139, in _go
    ret_value = fn(self, *arg, **kw)
                ^^^^^^^^^^^^^^^^^^^^
  File "/Users/apple/ProjectBackups/Flask_Packages/.venv/lib/python3.12/site-packages/sqlalchemy/orm/session.py", line 1232, in _prepare_impl
    self.session.flush()
  File "/Users/apple/ProjectBackups/Flask_Packages/.venv/lib/python3.12/site-packages/sqlalchemy/orm/session.py", line 4296, in flush
    self._flush(objects)
  File "/Users/apple/ProjectBackups/Flask_Packages/.venv/lib/python3.12/site-packages/sqlalchemy/orm/session.py", line 4431, in _flush
    with util.safe_reraise():
  File "/Users/apple/ProjectBackups/Flask_Packages/.venv/lib/python3.12/site-packages/sqlalchemy/util/langhelpers.py", line 146, in __exit__
    raise exc_value.with_traceback(exc_tb)
  File "/Users/apple/ProjectBackups/Flask_Packages/.venv/lib/python3.12/site-packages/sqlalchemy/orm/session.py", line 4392, in _flush
    flush_context.execute()
  File "/Users/apple/ProjectBackups/Flask_Packages/.venv/lib/python3.12/site-packages/sqlalchemy/orm/unitofwork.py", line 466, in execute
    rec.execute(self)
  File "/Users/apple/ProjectBackups/Flask_Packages/.venv/lib/python3.12/site-packages/sqlalchemy/orm/unitofwork.py", line 642, in execute
    util.preloaded.orm_persistence.save_obj(
  File "/Users/apple/ProjectBackups/Flask_Packages/.venv/lib/python3.12/site-packages/sqlalchemy/orm/persistence.py", line 85, in save_obj
    _emit_update_statements(
  File "/Users/apple/ProjectBackups/Flask_Packages/.venv/lib/python3.12/site-packages/sqlalchemy/orm/persistence.py", line 912, in _emit_update_statements
    c = connection.execute(
        ^^^^^^^^^^^^^^^^^^^
  File "/Users/apple/ProjectBackups/Flask_Packages/.venv/lib/python3.12/site-packages/sqlalchemy/engine/base.py", line 1408, in execute
    return meth(
           ^^^^^
  File "/Users/apple/ProjectBackups/Flask_Packages/.venv/lib/python3.12/site-packages/sqlalchemy/sql/elements.py", line 513, in _execute_on_connection
    return connection._execute_clauseelement(
           ^^^^^^^^^^^^^^^^^^^^^^^^^^^^^^^^^^
  File "/Users/apple/ProjectBackups/Flask_Packages/.venv/lib/python3.12/site-packages/sqlalchemy/engine/base.py", line 1630, in _execute_clauseelement
    ret = self._execute_context(
          ^^^^^^^^^^^^^^^^^^^^^^
  File "/Users/apple/ProjectBackups/Flask_Packages/.venv/lib/python3.12/site-packages/sqlalchemy/engine/base.py", line 1839, in _execute_context
    return self._exec_single_context(
           ^^^^^^^^^^^^^^^^^^^^^^^^^^
  File "/Users/apple/ProjectBackups/Flask_Packages/.venv/lib/python3.12/site-packages/sqlalchemy/engine/base.py", line 1979, in _exec_single_context
    self._handle_dbapi_exception(
  File "/Users/apple/ProjectBackups/Flask_Packages/.venv/lib/python3.12/site-packages/sqlalchemy/engine/base.py", line 2335, in _handle_dbapi_exception
    raise sqlalchemy_exception.with_traceback(exc_info[2]) from e
  File "/Users/apple/ProjectBackups/Flask_Packages/.venv/lib/python3.12/site-packages/sqlalchemy/engine/base.py", line 1960, in _exec_single_context
    self.dialect.do_execute(
  File "/Users/apple/ProjectBackups/Flask_Packages/.venv/lib/python3.12/site-packages/sqlalchemy/engine/default.py", line 924, in do_execute
    cursor.execute(statement, parameters)
sqlalchemy.exc.IntegrityError: (sqlite3.IntegrityError) UNIQUE constraint failed: user.first_name
[SQL: UPDATE user SET first_name=? WHERE user.id = ?]
[parameters: ('Divanstercheto', 1)]
(Background on this error at: https://sqlalche.me/e/20/gkpj)
2024-04-02 23:56:01,572 ERROR: Exception on /update-first-name [POST] [in /Users/apple/ProjectBackups/Flask_Packages/.venv/lib/python3.12/site-packages/flask/app.py:828]
Traceback (most recent call last):
  File "/Users/apple/ProjectBackups/Flask_Packages/.venv/lib/python3.12/site-packages/flask/app.py", line 1463, in wsgi_app
    response = self.full_dispatch_request()
               ^^^^^^^^^^^^^^^^^^^^^^^^^^^^
  File "/Users/apple/ProjectBackups/Flask_Packages/.venv/lib/python3.12/site-packages/flask/app.py", line 872, in full_dispatch_request
    rv = self.handle_user_exception(e)
         ^^^^^^^^^^^^^^^^^^^^^^^^^^^^^
  File "/Users/apple/ProjectBackups/Flask_Packages/.venv/lib/python3.12/site-packages/flask/app.py", line 870, in full_dispatch_request
    rv = self.dispatch_request()
         ^^^^^^^^^^^^^^^^^^^^^^^
  File "/Users/apple/ProjectBackups/Flask_Packages/.venv/lib/python3.12/site-packages/flask/app.py", line 855, in dispatch_request
    return self.ensure_sync(self.view_functions[rule.endpoint])(**view_args)  # type: ignore[no-any-return]
           ^^^^^^^^^^^^^^^^^^^^^^^^^^^^^^^^^^^^^^^^^^^^^^^^^^^^^^^^^^^^^^^^^
  File "/Users/apple/ProjectBackups/Flask_Packages/.venv/lib/python3.12/site-packages/flask_login/utils.py", line 290, in decorated_view
    return current_app.ensure_sync(func)(*args, **kwargs)
           ^^^^^^^^^^^^^^^^^^^^^^^^^^^^^^^^^^^^^^^^^^^^^^
  File "/Users/apple/ProjectBackups/Flask_Packages/website/auth/auth.py", line 97, in edit_profile
    return redirect(url_for('edit_profile'))
                    ^^^^^^^^^^^^^^^^^^^^^^^
  File "/Users/apple/ProjectBackups/Flask_Packages/.venv/lib/python3.12/site-packages/flask/helpers.py", line 220, in url_for
    return current_app.url_for(
           ^^^^^^^^^^^^^^^^^^^^
  File "/Users/apple/ProjectBackups/Flask_Packages/.venv/lib/python3.12/site-packages/flask/app.py", line 1074, in url_for
    return self.handle_url_build_error(error, endpoint, values)
           ^^^^^^^^^^^^^^^^^^^^^^^^^^^^^^^^^^^^^^^^^^^^^^^^^^^^
  File "/Users/apple/ProjectBackups/Flask_Packages/.venv/lib/python3.12/site-packages/flask/app.py", line 1063, in url_for
    rv = url_adapter.build(  # type: ignore[union-attr]
         ^^^^^^^^^^^^^^^^^^^^^^^^^^^^^^^^^^^^^^^^^^^^^^
  File "/Users/apple/ProjectBackups/Flask_Packages/.venv/lib/python3.12/site-packages/werkzeug/routing/map.py", line 919, in build
    raise BuildError(endpoint, values, method, self)
werkzeug.routing.exceptions.BuildError: Could not build url for endpoint 'edit_profile'. Did you mean 'auth.edit_profile' instead?
2024-04-02 23:57:22,371 INFO: Microblog startup [in /Users/apple/ProjectBackups/Flask_Packages/website/__init__.py:89]
