2024-03-28 17:11:02,801 ERROR: Exception on /messages [GET] [in /Users/apple/ProjectBackups/Flask_Packages/.venv/lib/python3.12/site-packages/flask/app.py:828]
Traceback (most recent call last):
  File "/Users/apple/ProjectBackups/Flask_Packages/.venv/lib/python3.12/site-packages/flask/app.py", line 1463, in wsgi_app
    response = self.full_dispatch_request()
               ^^^^^^^^^^^^^^^^^^^^^^^^^^^^
  File "/Users/apple/ProjectBackups/Flask_Packages/.venv/lib/python3.12/site-packages/flask/app.py", line 872, in full_dispatch_request
    rv = self.handle_user_exception(e)
         ^^^^^^^^^^^^^^^^^^^^^^^^^^^^^
  File "/Users/apple/ProjectBackups/Flask_Packages/.venv/lib/python3.12/site-packages/flask/app.py", line 870, in full_dispatch_request
    rv = self.dispatch_request()
         ^^^^^^^^^^^^^^^^^^^^^^^
  File "/Users/apple/ProjectBackups/Flask_Packages/.venv/lib/python3.12/site-packages/flask/app.py", line 855, in dispatch_request
    return self.ensure_sync(self.view_functions[rule.endpoint])(**view_args)  # type: ignore[no-any-return]
           ^^^^^^^^^^^^^^^^^^^^^^^^^^^^^^^^^^^^^^^^^^^^^^^^^^^^^^^^^^^^^^^^^
  File "/Users/apple/ProjectBackups/Flask_Packages/.venv/lib/python3.12/site-packages/flask_login/utils.py", line 290, in decorated_view
    return current_app.ensure_sync(func)(*args, **kwargs)
           ^^^^^^^^^^^^^^^^^^^^^^^^^^^^^^^^^^^^^^^^^^^^^^
  File "/Users/apple/ProjectBackups/Flask_Packages/website/views/views.py", line 337, in messages
    return render_template('messages.html', messages=messages.items,
           ^^^^^^^^^^^^^^^^^^^^^^^^^^^^^^^^^^^^^^^^^^^^^^^^^^^^^^^^^
  File "/Users/apple/ProjectBackups/Flask_Packages/.venv/lib/python3.12/site-packages/flask/templating.py", line 149, in render_template
    template = app.jinja_env.get_or_select_template(template_name_or_list)
               ^^^^^^^^^^^^^^^^^^^^^^^^^^^^^^^^^^^^^^^^^^^^^^^^^^^^^^^^^^^
  File "/Users/apple/ProjectBackups/Flask_Packages/.venv/lib/python3.12/site-packages/jinja2/environment.py", line 1081, in get_or_select_template
    return self.get_template(template_name_or_list, parent, globals)
           ^^^^^^^^^^^^^^^^^^^^^^^^^^^^^^^^^^^^^^^^^^^^^^^^^^^^^^^^^
  File "/Users/apple/ProjectBackups/Flask_Packages/.venv/lib/python3.12/site-packages/jinja2/environment.py", line 1010, in get_template
    return self._load_template(name, globals)
           ^^^^^^^^^^^^^^^^^^^^^^^^^^^^^^^^^^
  File "/Users/apple/ProjectBackups/Flask_Packages/.venv/lib/python3.12/site-packages/jinja2/environment.py", line 969, in _load_template
    template = self.loader.load(self, name, self.make_globals(globals))
               ^^^^^^^^^^^^^^^^^^^^^^^^^^^^^^^^^^^^^^^^^^^^^^^^^^^^^^^^
  File "/Users/apple/ProjectBackups/Flask_Packages/.venv/lib/python3.12/site-packages/jinja2/loaders.py", line 137, in load
    code = environment.compile(source, name, filename)
           ^^^^^^^^^^^^^^^^^^^^^^^^^^^^^^^^^^^^^^^^^^^
  File "/Users/apple/ProjectBackups/Flask_Packages/.venv/lib/python3.12/site-packages/jinja2/environment.py", line 768, in compile
    self.handle_exception(source=source_hint)
  File "/Users/apple/ProjectBackups/Flask_Packages/.venv/lib/python3.12/site-packages/jinja2/environment.py", line 936, in handle_exception
    raise rewrite_traceback_stack(source=source)
  File "/Users/apple/ProjectBackups/Flask_Packages/website/templates/messages.html", line 9, in template
    <a href="{% url 'user_profile' message.author.username %}">
    ^^^^^^^^^^^^^^^^^^^^^^^^^
jinja2.exceptions.TemplateSyntaxError: Encountered unknown tag 'url'. Jinja was looking for the following tags: 'endfor' or 'else'. The innermost block that needs to be closed is 'for'.
2024-03-28 17:11:59,420 INFO: Microblog startup [in /Users/apple/ProjectBackups/Flask_Packages/website/__init__.py:89]
2024-03-28 17:12:05,343 ERROR: Exception on /messages [GET] [in /Users/apple/ProjectBackups/Flask_Packages/.venv/lib/python3.12/site-packages/flask/app.py:828]
Traceback (most recent call last):
  File "/Users/apple/ProjectBackups/Flask_Packages/.venv/lib/python3.12/site-packages/flask/app.py", line 1463, in wsgi_app
    response = self.full_dispatch_request()
               ^^^^^^^^^^^^^^^^^^^^^^^^^^^^
  File "/Users/apple/ProjectBackups/Flask_Packages/.venv/lib/python3.12/site-packages/flask/app.py", line 872, in full_dispatch_request
    rv = self.handle_user_exception(e)
         ^^^^^^^^^^^^^^^^^^^^^^^^^^^^^
  File "/Users/apple/ProjectBackups/Flask_Packages/.venv/lib/python3.12/site-packages/flask/app.py", line 870, in full_dispatch_request
    rv = self.dispatch_request()
         ^^^^^^^^^^^^^^^^^^^^^^^
  File "/Users/apple/ProjectBackups/Flask_Packages/.venv/lib/python3.12/site-packages/flask/app.py", line 855, in dispatch_request
    return self.ensure_sync(self.view_functions[rule.endpoint])(**view_args)  # type: ignore[no-any-return]
           ^^^^^^^^^^^^^^^^^^^^^^^^^^^^^^^^^^^^^^^^^^^^^^^^^^^^^^^^^^^^^^^^^
  File "/Users/apple/ProjectBackups/Flask_Packages/.venv/lib/python3.12/site-packages/flask_login/utils.py", line 290, in decorated_view
    return current_app.ensure_sync(func)(*args, **kwargs)
           ^^^^^^^^^^^^^^^^^^^^^^^^^^^^^^^^^^^^^^^^^^^^^^
  File "/Users/apple/ProjectBackups/Flask_Packages/website/views/views.py", line 337, in messages
    return render_template('messages.html', messages=messages.items,
           ^^^^^^^^^^^^^^^^^^^^^^^^^^^^^^^^^^^^^^^^^^^^^^^^^^^^^^^^^
  File "/Users/apple/ProjectBackups/Flask_Packages/.venv/lib/python3.12/site-packages/flask/templating.py", line 150, in render_template
    return _render(app, template, context)
           ^^^^^^^^^^^^^^^^^^^^^^^^^^^^^^^
  File "/Users/apple/ProjectBackups/Flask_Packages/.venv/lib/python3.12/site-packages/flask/templating.py", line 131, in _render
    rv = template.render(context)
         ^^^^^^^^^^^^^^^^^^^^^^^^
  File "/Users/apple/ProjectBackups/Flask_Packages/.venv/lib/python3.12/site-packages/jinja2/environment.py", line 1301, in render
    self.environment.handle_exception()
  File "/Users/apple/ProjectBackups/Flask_Packages/.venv/lib/python3.12/site-packages/jinja2/environment.py", line 936, in handle_exception
    raise rewrite_traceback_stack(source=source)
  File "/Users/apple/ProjectBackups/Flask_Packages/website/templates/messages.html", line 1, in top-level template code
    {% extends "base.html" %}
  File "/Users/apple/ProjectBackups/Flask_Packages/website/templates/base.html", line 65, in top-level template code
    {% block content %}{% endblock %}
    ^^^^^^^^^^^^^^^^^^^^^^^^^
  File "/Users/apple/ProjectBackups/Flask_Packages/website/templates/messages.html", line 8, in block 'content'
    <p><strong>From:</strong> <a href="{{ url_for('views.profile', user_id=message.author.id) }}">{{ message.author.first_name }}</a></p>
    ^^^^^^^^^^^^^^^^^^^^^^^^^
  File "/Users/apple/ProjectBackups/Flask_Packages/.venv/lib/python3.12/site-packages/flask/app.py", line 1074, in url_for
    return self.handle_url_build_error(error, endpoint, values)
           ^^^^^^^^^^^^^^^^^^^^^^^^^^^^^^^^^^^^^^^^^^^^^^^^^^^^
  File "/Users/apple/ProjectBackups/Flask_Packages/.venv/lib/python3.12/site-packages/flask/app.py", line 1063, in url_for
    rv = url_adapter.build(  # type: ignore[union-attr]
         ^^^^^^^^^^^^^^^^^^^^^^^^^^^^^^^^^^^^^^^^^^^^^^
  File "/Users/apple/ProjectBackups/Flask_Packages/.venv/lib/python3.12/site-packages/werkzeug/routing/map.py", line 919, in build
    raise BuildError(endpoint, values, method, self)
werkzeug.routing.exceptions.BuildError: Could not build url for endpoint 'views.profile' with values ['user_id']. Did you forget to specify values ['first_name']?
