2024-03-22 20:27:05,039 ERROR: Exception on /blogpost [GET] [in /Users/apple/ProjectBackups/Flask_Packages/.venv/lib/python3.12/site-packages/flask/app.py:828]
Traceback (most recent call last):
  File "/Users/apple/ProjectBackups/Flask_Packages/.venv/lib/python3.12/site-packages/flask/app.py", line 1463, in wsgi_app
    response = self.full_dispatch_request()
               ^^^^^^^^^^^^^^^^^^^^^^^^^^^^
  File "/Users/apple/ProjectBackups/Flask_Packages/.venv/lib/python3.12/site-packages/flask/app.py", line 872, in full_dispatch_request
    rv = self.handle_user_exception(e)
         ^^^^^^^^^^^^^^^^^^^^^^^^^^^^^
  File "/Users/apple/ProjectBackups/Flask_Packages/.venv/lib/python3.12/site-packages/flask/app.py", line 870, in full_dispatch_request
    rv = self.dispatch_request()
         ^^^^^^^^^^^^^^^^^^^^^^^
  File "/Users/apple/ProjectBackups/Flask_Packages/.venv/lib/python3.12/site-packages/flask/app.py", line 855, in dispatch_request
    return self.ensure_sync(self.view_functions[rule.endpoint])(**view_args)  # type: ignore[no-any-return]
           ^^^^^^^^^^^^^^^^^^^^^^^^^^^^^^^^^^^^^^^^^^^^^^^^^^^^^^^^^^^^^^^^^
  File "/Users/apple/ProjectBackups/Flask_Packages/.venv/lib/python3.12/site-packages/flask_login/utils.py", line 290, in decorated_view
    return current_app.ensure_sync(func)(*args, **kwargs)
           ^^^^^^^^^^^^^^^^^^^^^^^^^^^^^^^^^^^^^^^^^^^^^^
  File "/Users/apple/ProjectBackups/Flask_Packages/website/views/views.py", line 112, in blogpost
    return render_template('blogpost.html', post_form=post_form, comment_form=comment_form,
           ^^^^^^^^^^^^^^^^^^^^^^^^^^^^^^^^^^^^^^^^^^^^^^^^^^^^^^^^^^^^^^^^^^^^^^^^^^^^^^^^
  File "/Users/apple/ProjectBackups/Flask_Packages/.venv/lib/python3.12/site-packages/flask/templating.py", line 149, in render_template
    template = app.jinja_env.get_or_select_template(template_name_or_list)
               ^^^^^^^^^^^^^^^^^^^^^^^^^^^^^^^^^^^^^^^^^^^^^^^^^^^^^^^^^^^
  File "/Users/apple/ProjectBackups/Flask_Packages/.venv/lib/python3.12/site-packages/jinja2/environment.py", line 1081, in get_or_select_template
    return self.get_template(template_name_or_list, parent, globals)
           ^^^^^^^^^^^^^^^^^^^^^^^^^^^^^^^^^^^^^^^^^^^^^^^^^^^^^^^^^
  File "/Users/apple/ProjectBackups/Flask_Packages/.venv/lib/python3.12/site-packages/jinja2/environment.py", line 1010, in get_template
    return self._load_template(name, globals)
           ^^^^^^^^^^^^^^^^^^^^^^^^^^^^^^^^^^
  File "/Users/apple/ProjectBackups/Flask_Packages/.venv/lib/python3.12/site-packages/jinja2/environment.py", line 969, in _load_template
    template = self.loader.load(self, name, self.make_globals(globals))
               ^^^^^^^^^^^^^^^^^^^^^^^^^^^^^^^^^^^^^^^^^^^^^^^^^^^^^^^^
  File "/Users/apple/ProjectBackups/Flask_Packages/.venv/lib/python3.12/site-packages/jinja2/loaders.py", line 137, in load
    code = environment.compile(source, name, filename)
           ^^^^^^^^^^^^^^^^^^^^^^^^^^^^^^^^^^^^^^^^^^^
  File "/Users/apple/ProjectBackups/Flask_Packages/.venv/lib/python3.12/site-packages/jinja2/environment.py", line 768, in compile
    self.handle_exception(source=source_hint)
  File "/Users/apple/ProjectBackups/Flask_Packages/.venv/lib/python3.12/site-packages/jinja2/environment.py", line 936, in handle_exception
    raise rewrite_traceback_stack(source=source)
  File "/Users/apple/ProjectBackups/Flask_Packages/website/templates/blogpost.html", line 163, in template
    {% block javascript %}
jinja2.exceptions.TemplateAssertionError: block 'javascript' defined twice
2024-03-22 20:27:52,592 INFO: Microblog startup [in /Users/apple/ProjectBackups/Flask_Packages/website/__init__.py:88]
2024-03-22 20:41:53,539 INFO: Microblog startup [in /Users/apple/ProjectBackups/Flask_Packages/website/__init__.py:88]
2024-03-22 20:46:54,607 INFO: Microblog startup [in /Users/apple/ProjectBackups/Flask_Packages/website/__init__.py:88]
2024-03-22 20:50:46,645 INFO: Microblog startup [in /Users/apple/ProjectBackups/Flask_Packages/website/__init__.py:88]
2024-03-22 20:54:35,968 INFO: Microblog startup [in /Users/apple/ProjectBackups/Flask_Packages/website/__init__.py:88]
2024-03-22 20:55:02,329 INFO: Microblog startup [in /Users/apple/ProjectBackups/Flask_Packages/website/__init__.py:88]
2024-03-22 20:56:33,458 INFO: Microblog startup [in /Users/apple/ProjectBackups/Flask_Packages/website/__init__.py:88]
2024-03-22 20:56:54,930 INFO: Microblog startup [in /Users/apple/ProjectBackups/Flask_Packages/website/__init__.py:88]
2024-03-22 20:57:00,392 INFO: Microblog startup [in /Users/apple/ProjectBackups/Flask_Packages/website/__init__.py:88]
2024-03-22 20:57:27,548 INFO: Microblog startup [in /Users/apple/ProjectBackups/Flask_Packages/website/__init__.py:88]
2024-03-22 22:16:34,811 INFO: Microblog startup [in /Users/apple/ProjectBackups/Flask_Packages/website/__init__.py:88]
2024-03-22 22:18:35,715 INFO: Microblog startup [in /Users/apple/ProjectBackups/Flask_Packages/website/__init__.py:88]
2024-03-22 22:18:42,204 ERROR: Exception on /messages [GET] [in /Users/apple/ProjectBackups/Flask_Packages/.venv/lib/python3.12/site-packages/flask/app.py:828]
Traceback (most recent call last):
  File "/Users/apple/ProjectBackups/Flask_Packages/.venv/lib/python3.12/site-packages/flask/app.py", line 1463, in wsgi_app
    response = self.full_dispatch_request()
               ^^^^^^^^^^^^^^^^^^^^^^^^^^^^
  File "/Users/apple/ProjectBackups/Flask_Packages/.venv/lib/python3.12/site-packages/flask/app.py", line 872, in full_dispatch_request
    rv = self.handle_user_exception(e)
         ^^^^^^^^^^^^^^^^^^^^^^^^^^^^^
  File "/Users/apple/ProjectBackups/Flask_Packages/.venv/lib/python3.12/site-packages/flask/app.py", line 870, in full_dispatch_request
    rv = self.dispatch_request()
         ^^^^^^^^^^^^^^^^^^^^^^^
  File "/Users/apple/ProjectBackups/Flask_Packages/.venv/lib/python3.12/site-packages/flask/app.py", line 855, in dispatch_request
    return self.ensure_sync(self.view_functions[rule.endpoint])(**view_args)  # type: ignore[no-any-return]
           ^^^^^^^^^^^^^^^^^^^^^^^^^^^^^^^^^^^^^^^^^^^^^^^^^^^^^^^^^^^^^^^^^
  File "/Users/apple/ProjectBackups/Flask_Packages/.venv/lib/python3.12/site-packages/flask_login/utils.py", line 290, in decorated_view
    return current_app.ensure_sync(func)(*args, **kwargs)
           ^^^^^^^^^^^^^^^^^^^^^^^^^^^^^^^^^^^^^^^^^^^^^^
  File "/Users/apple/ProjectBackups/Flask_Packages/website/views/views.py", line 336, in messages
    return render_template('messages.html', messages=messages.items,
           ^^^^^^^^^^^^^^^^^^^^^^^^^^^^^^^^^^^^^^^^^^^^^^^^^^^^^^^^^
  File "/Users/apple/ProjectBackups/Flask_Packages/.venv/lib/python3.12/site-packages/flask/templating.py", line 150, in render_template
    return _render(app, template, context)
           ^^^^^^^^^^^^^^^^^^^^^^^^^^^^^^^
  File "/Users/apple/ProjectBackups/Flask_Packages/.venv/lib/python3.12/site-packages/flask/templating.py", line 131, in _render
    rv = template.render(context)
         ^^^^^^^^^^^^^^^^^^^^^^^^
  File "/Users/apple/ProjectBackups/Flask_Packages/.venv/lib/python3.12/site-packages/jinja2/environment.py", line 1301, in render
    self.environment.handle_exception()
  File "/Users/apple/ProjectBackups/Flask_Packages/.venv/lib/python3.12/site-packages/jinja2/environment.py", line 936, in handle_exception
    raise rewrite_traceback_stack(source=source)
  File "/Users/apple/ProjectBackups/Flask_Packages/website/templates/messages.html", line 1, in top-level template code
    {% extends "base.html" %}
  File "/Users/apple/ProjectBackups/Flask_Packages/website/templates/base.html", line 13, in top-level template code
    {% include 'navbar.html' %}
    ^^^^^^^^^^^^^^^^^^^^^^^^^
  File "/Users/apple/ProjectBackups/Flask_Packages/website/templates/navbar.html", line 15, in top-level template code
    {% set unread_message_count = current_user.unread_message_count() %}
    ^^^^^^^^^^^^^^^^^^^^^^^^^
TypeError: 'int' object is not callable
