2024-03-26 00:00:05,351 ERROR: Exception on /sign-up [POST] [in /Users/apple/ProjectBackups/Flask_Packages/.venv/lib/python3.12/site-packages/flask/app.py:828]
Traceback (most recent call last):
  File "/Users/apple/ProjectBackups/Flask_Packages/.venv/lib/python3.12/site-packages/sqlalchemy/engine/base.py", line 1960, in _exec_single_context
    self.dialect.do_execute(
  File "/Users/apple/ProjectBackups/Flask_Packages/.venv/lib/python3.12/site-packages/sqlalchemy/engine/default.py", line 924, in do_execute
    cursor.execute(statement, parameters)
sqlite3.IntegrityError: UNIQUE constraint failed: user.first_name

The above exception was the direct cause of the following exception:

Traceback (most recent call last):
  File "/Users/apple/ProjectBackups/Flask_Packages/.venv/lib/python3.12/site-packages/flask/app.py", line 1463, in wsgi_app
    response = self.full_dispatch_request()
               ^^^^^^^^^^^^^^^^^^^^^^^^^^^^
  File "/Users/apple/ProjectBackups/Flask_Packages/.venv/lib/python3.12/site-packages/flask/app.py", line 872, in full_dispatch_request
    rv = self.handle_user_exception(e)
         ^^^^^^^^^^^^^^^^^^^^^^^^^^^^^
  File "/Users/apple/ProjectBackups/Flask_Packages/.venv/lib/python3.12/site-packages/flask/app.py", line 870, in full_dispatch_request
    rv = self.dispatch_request()
         ^^^^^^^^^^^^^^^^^^^^^^^
  File "/Users/apple/ProjectBackups/Flask_Packages/.venv/lib/python3.12/site-packages/flask/app.py", line 855, in dispatch_request
    return self.ensure_sync(self.view_functions[rule.endpoint])(**view_args)  # type: ignore[no-any-return]
           ^^^^^^^^^^^^^^^^^^^^^^^^^^^^^^^^^^^^^^^^^^^^^^^^^^^^^^^^^^^^^^^^^
  File "/Users/apple/ProjectBackups/Flask_Packages/website/auth/auth.py", line 58, in sign_up
    db.session.commit()
  File "/Users/apple/ProjectBackups/Flask_Packages/.venv/lib/python3.12/site-packages/sqlalchemy/orm/scoping.py", line 597, in commit
    return self._proxied.commit()
           ^^^^^^^^^^^^^^^^^^^^^^
  File "/Users/apple/ProjectBackups/Flask_Packages/.venv/lib/python3.12/site-packages/sqlalchemy/orm/session.py", line 1972, in commit
    trans.commit(_to_root=True)
  File "<string>", line 2, in commit
  File "/Users/apple/ProjectBackups/Flask_Packages/.venv/lib/python3.12/site-packages/sqlalchemy/orm/state_changes.py", line 139, in _go
    ret_value = fn(self, *arg, **kw)
                ^^^^^^^^^^^^^^^^^^^^
  File "/Users/apple/ProjectBackups/Flask_Packages/.venv/lib/python3.12/site-packages/sqlalchemy/orm/session.py", line 1257, in commit
    self._prepare_impl()
  File "<string>", line 2, in _prepare_impl
  File "/Users/apple/ProjectBackups/Flask_Packages/.venv/lib/python3.12/site-packages/sqlalchemy/orm/state_changes.py", line 139, in _go
    ret_value = fn(self, *arg, **kw)
                ^^^^^^^^^^^^^^^^^^^^
  File "/Users/apple/ProjectBackups/Flask_Packages/.venv/lib/python3.12/site-packages/sqlalchemy/orm/session.py", line 1232, in _prepare_impl
    self.session.flush()
  File "/Users/apple/ProjectBackups/Flask_Packages/.venv/lib/python3.12/site-packages/sqlalchemy/orm/session.py", line 4296, in flush
    self._flush(objects)
  File "/Users/apple/ProjectBackups/Flask_Packages/.venv/lib/python3.12/site-packages/sqlalchemy/orm/session.py", line 4431, in _flush
    with util.safe_reraise():
  File "/Users/apple/ProjectBackups/Flask_Packages/.venv/lib/python3.12/site-packages/sqlalchemy/util/langhelpers.py", line 146, in __exit__
    raise exc_value.with_traceback(exc_tb)
  File "/Users/apple/ProjectBackups/Flask_Packages/.venv/lib/python3.12/site-packages/sqlalchemy/orm/session.py", line 4392, in _flush
    flush_context.execute()
  File "/Users/apple/ProjectBackups/Flask_Packages/.venv/lib/python3.12/site-packages/sqlalchemy/orm/unitofwork.py", line 466, in execute
    rec.execute(self)
  File "/Users/apple/ProjectBackups/Flask_Packages/.venv/lib/python3.12/site-packages/sqlalchemy/orm/unitofwork.py", line 642, in execute
    util.preloaded.orm_persistence.save_obj(
  File "/Users/apple/ProjectBackups/Flask_Packages/.venv/lib/python3.12/site-packages/sqlalchemy/orm/persistence.py", line 93, in save_obj
    _emit_insert_statements(
  File "/Users/apple/ProjectBackups/Flask_Packages/.venv/lib/python3.12/site-packages/sqlalchemy/orm/persistence.py", line 1233, in _emit_insert_statements
    result = connection.execute(
             ^^^^^^^^^^^^^^^^^^^
  File "/Users/apple/ProjectBackups/Flask_Packages/.venv/lib/python3.12/site-packages/sqlalchemy/engine/base.py", line 1408, in execute
    return meth(
           ^^^^^
  File "/Users/apple/ProjectBackups/Flask_Packages/.venv/lib/python3.12/site-packages/sqlalchemy/sql/elements.py", line 513, in _execute_on_connection
    return connection._execute_clauseelement(
           ^^^^^^^^^^^^^^^^^^^^^^^^^^^^^^^^^^
  File "/Users/apple/ProjectBackups/Flask_Packages/.venv/lib/python3.12/site-packages/sqlalchemy/engine/base.py", line 1630, in _execute_clauseelement
    ret = self._execute_context(
          ^^^^^^^^^^^^^^^^^^^^^^
  File "/Users/apple/ProjectBackups/Flask_Packages/.venv/lib/python3.12/site-packages/sqlalchemy/engine/base.py", line 1839, in _execute_context
    return self._exec_single_context(
           ^^^^^^^^^^^^^^^^^^^^^^^^^^
  File "/Users/apple/ProjectBackups/Flask_Packages/.venv/lib/python3.12/site-packages/sqlalchemy/engine/base.py", line 1979, in _exec_single_context
    self._handle_dbapi_exception(
  File "/Users/apple/ProjectBackups/Flask_Packages/.venv/lib/python3.12/site-packages/sqlalchemy/engine/base.py", line 2335, in _handle_dbapi_exception
    raise sqlalchemy_exception.with_traceback(exc_info[2]) from e
  File "/Users/apple/ProjectBackups/Flask_Packages/.venv/lib/python3.12/site-packages/sqlalchemy/engine/base.py", line 1960, in _exec_single_context
    self.dialect.do_execute(
  File "/Users/apple/ProjectBackups/Flask_Packages/.venv/lib/python3.12/site-packages/sqlalchemy/engine/default.py", line 924, in do_execute
    cursor.execute(statement, parameters)
sqlalchemy.exc.IntegrityError: (sqlite3.IntegrityError) UNIQUE constraint failed: user.first_name
[SQL: INSERT INTO user (email, password, first_name, last_seen, about_me, timezone, registered_at, last_message_read_time) VALUES (?, ?, ?, ?, ?, ?, ?, ?)]
[parameters: ('divanster@gmail.com', 'pbkdf2:sha256:600000$drZJiubHPRbdJ4LJ$283e193c506d8630293b217b71f2f60739b1b2d51077fc968fcba6c333d2c7b9', 'Ivan', '2024-03-25 22:00:05.350380', None, None, '2024-03-25 22:00:05.350383', None)]
(Background on this error at: https://sqlalche.me/e/20/gkpj)
2024-03-26 00:04:28,697 INFO: Microblog startup [in /Users/apple/ProjectBackups/Flask_Packages/website/__init__.py:89]
2024-03-26 00:05:38,720 ERROR: Exception on /reset_password/eyJhbGciOiJIUzI1NiIsInR5cCI6IkpXVCJ9.eyJyZXNldF9wYXNzd29yZCI6NiwiZXhwIjoxNzExNDA0ODc4LjY0ODYzOX0.OLvZhMbFJIcT4k1iOiMCYr3iN6Okhh7JWAJbnaUaSYo [GET] [in /Users/apple/ProjectBackups/Flask_Packages/.venv/lib/python3.12/site-packages/flask/app.py:828]
Traceback (most recent call last):
  File "/Users/apple/ProjectBackups/Flask_Packages/.venv/lib/python3.12/site-packages/flask/app.py", line 1463, in wsgi_app
    response = self.full_dispatch_request()
               ^^^^^^^^^^^^^^^^^^^^^^^^^^^^
  File "/Users/apple/ProjectBackups/Flask_Packages/.venv/lib/python3.12/site-packages/flask/app.py", line 872, in full_dispatch_request
    rv = self.handle_user_exception(e)
         ^^^^^^^^^^^^^^^^^^^^^^^^^^^^^
  File "/Users/apple/ProjectBackups/Flask_Packages/.venv/lib/python3.12/site-packages/flask/app.py", line 870, in full_dispatch_request
    rv = self.dispatch_request()
         ^^^^^^^^^^^^^^^^^^^^^^^
  File "/Users/apple/ProjectBackups/Flask_Packages/.venv/lib/python3.12/site-packages/flask/app.py", line 855, in dispatch_request
    return self.ensure_sync(self.view_functions[rule.endpoint])(**view_args)  # type: ignore[no-any-return]
           ^^^^^^^^^^^^^^^^^^^^^^^^^^^^^^^^^^^^^^^^^^^^^^^^^^^^^^^^^^^^^^^^^
  File "/Users/apple/ProjectBackups/Flask_Packages/website/auth/auth.py", line 127, in reset_password
    return render_template('reset_password.html', form=form)
           ^^^^^^^^^^^^^^^^^^^^^^^^^^^^^^^^^^^^^^^^^^^^^^^^^
  File "/Users/apple/ProjectBackups/Flask_Packages/.venv/lib/python3.12/site-packages/flask/templating.py", line 150, in render_template
    return _render(app, template, context)
           ^^^^^^^^^^^^^^^^^^^^^^^^^^^^^^^
  File "/Users/apple/ProjectBackups/Flask_Packages/.venv/lib/python3.12/site-packages/flask/templating.py", line 131, in _render
    rv = template.render(context)
         ^^^^^^^^^^^^^^^^^^^^^^^^
  File "/Users/apple/ProjectBackups/Flask_Packages/.venv/lib/python3.12/site-packages/jinja2/environment.py", line 1301, in render
    self.environment.handle_exception()
  File "/Users/apple/ProjectBackups/Flask_Packages/.venv/lib/python3.12/site-packages/jinja2/environment.py", line 936, in handle_exception
    raise rewrite_traceback_stack(source=source)
  File "/Users/apple/ProjectBackups/Flask_Packages/website/templates/reset_password.html", line 1, in top-level template code
    Dear {{ user.first_name }},
    ^^^^^^^^^^^^^^^^^^^^^^^^^
  File "/Users/apple/ProjectBackups/Flask_Packages/.venv/lib/python3.12/site-packages/jinja2/environment.py", line 485, in getattr
    return getattr(obj, attribute)
           ^^^^^^^^^^^^^^^^^^^^^^^
jinja2.exceptions.UndefinedError: 'user' is undefined
2024-03-26 00:06:56,792 INFO: Microblog startup [in /Users/apple/ProjectBackups/Flask_Packages/website/__init__.py:89]
2024-03-26 00:17:55,811 INFO: Microblog startup [in /Users/apple/ProjectBackups/Flask_Packages/website/__init__.py:89]
2024-03-26 00:21:10,168 INFO: Microblog startup [in /Users/apple/ProjectBackups/Flask_Packages/website/__init__.py:89]
2024-03-26 00:24:01,505 INFO: Microblog startup [in /Users/apple/ProjectBackups/Flask_Packages/website/__init__.py:89]
2024-03-26 17:19:34,759 INFO: Microblog startup [in /Users/apple/ProjectBackups/Flask_Packages/website/__init__.py:89]
2024-03-26 17:43:12,606 INFO: Microblog startup [in /Users/apple/ProjectBackups/Flask_Packages/website/__init__.py:89]
2024-03-26 17:43:34,518 INFO: Microblog startup [in /Users/apple/ProjectBackups/Flask_Packages/website/__init__.py:89]
